2024-01-12 19:15:45,308 ERROR: Exception on /edit_profile [POST] [in C:\Users\Cucha\microblog\venv\Lib\site-packages\flask\app.py:825]
Traceback (most recent call last):
  File "C:\Users\Cucha\microblog\venv\Lib\site-packages\sqlalchemy\engine\base.py", line 1969, in _exec_single_context
    self.dialect.do_execute(
  File "C:\Users\Cucha\microblog\venv\Lib\site-packages\sqlalchemy\engine\default.py", line 922, in do_execute
    cursor.execute(statement, parameters)
sqlite3.IntegrityError: UNIQUE constraint failed: user.username

The above exception was the direct cause of the following exception:

Traceback (most recent call last):
  File "C:\Users\Cucha\microblog\venv\Lib\site-packages\flask\app.py", line 1455, in wsgi_app
    response = self.full_dispatch_request()
               ^^^^^^^^^^^^^^^^^^^^^^^^^^^^
  File "C:\Users\Cucha\microblog\venv\Lib\site-packages\flask\app.py", line 869, in full_dispatch_request
    rv = self.handle_user_exception(e)
         ^^^^^^^^^^^^^^^^^^^^^^^^^^^^^
  File "C:\Users\Cucha\microblog\venv\Lib\site-packages\flask\app.py", line 867, in full_dispatch_request
    rv = self.dispatch_request()
         ^^^^^^^^^^^^^^^^^^^^^^^
  File "C:\Users\Cucha\microblog\venv\Lib\site-packages\flask\app.py", line 852, in dispatch_request
    return self.ensure_sync(self.view_functions[rule.endpoint])(**view_args)
           ^^^^^^^^^^^^^^^^^^^^^^^^^^^^^^^^^^^^^^^^^^^^^^^^^^^^^^^^^^^^^^^^^
  File "C:\Users\Cucha\microblog\venv\Lib\site-packages\flask_login\utils.py", line 290, in decorated_view
    return current_app.ensure_sync(func)(*args, **kwargs)
           ^^^^^^^^^^^^^^^^^^^^^^^^^^^^^^^^^^^^^^^^^^^^^^
  File "C:\Users\Cucha\microblog\app\routes.py", line 90, in edit_profile
    db.session.commit()
  File "C:\Users\Cucha\microblog\venv\Lib\site-packages\sqlalchemy\orm\scoping.py", line 598, in commit
    return self._proxied.commit()
           ^^^^^^^^^^^^^^^^^^^^^^
  File "C:\Users\Cucha\microblog\venv\Lib\site-packages\sqlalchemy\orm\session.py", line 1969, in commit
    trans.commit(_to_root=True)
  File "<string>", line 2, in commit
  File "C:\Users\Cucha\microblog\venv\Lib\site-packages\sqlalchemy\orm\state_changes.py", line 139, in _go
    ret_value = fn(self, *arg, **kw)
                ^^^^^^^^^^^^^^^^^^^^
  File "C:\Users\Cucha\microblog\venv\Lib\site-packages\sqlalchemy\orm\session.py", line 1256, in commit
    self._prepare_impl()
  File "<string>", line 2, in _prepare_impl
  File "C:\Users\Cucha\microblog\venv\Lib\site-packages\sqlalchemy\orm\state_changes.py", line 139, in _go
    ret_value = fn(self, *arg, **kw)
                ^^^^^^^^^^^^^^^^^^^^
  File "C:\Users\Cucha\microblog\venv\Lib\site-packages\sqlalchemy\orm\session.py", line 1231, in _prepare_impl
    self.session.flush()
  File "C:\Users\Cucha\microblog\venv\Lib\site-packages\sqlalchemy\orm\session.py", line 4312, in flush
    self._flush(objects)
  File "C:\Users\Cucha\microblog\venv\Lib\site-packages\sqlalchemy\orm\session.py", line 4447, in _flush
    with util.safe_reraise():
  File "C:\Users\Cucha\microblog\venv\Lib\site-packages\sqlalchemy\util\langhelpers.py", line 146, in __exit__
    raise exc_value.with_traceback(exc_tb)
  File "C:\Users\Cucha\microblog\venv\Lib\site-packages\sqlalchemy\orm\session.py", line 4408, in _flush
    flush_context.execute()
  File "C:\Users\Cucha\microblog\venv\Lib\site-packages\sqlalchemy\orm\unitofwork.py", line 466, in execute
    rec.execute(self)
  File "C:\Users\Cucha\microblog\venv\Lib\site-packages\sqlalchemy\orm\unitofwork.py", line 642, in execute
    util.preloaded.orm_persistence.save_obj(
  File "C:\Users\Cucha\microblog\venv\Lib\site-packages\sqlalchemy\orm\persistence.py", line 85, in save_obj
    _emit_update_statements(
  File "C:\Users\Cucha\microblog\venv\Lib\site-packages\sqlalchemy\orm\persistence.py", line 910, in _emit_update_statements
    c = connection.execute(
        ^^^^^^^^^^^^^^^^^^^
  File "C:\Users\Cucha\microblog\venv\Lib\site-packages\sqlalchemy\engine\base.py", line 1416, in execute
    return meth(
           ^^^^^
  File "C:\Users\Cucha\microblog\venv\Lib\site-packages\sqlalchemy\sql\elements.py", line 517, in _execute_on_connection
    return connection._execute_clauseelement(
           ^^^^^^^^^^^^^^^^^^^^^^^^^^^^^^^^^^
  File "C:\Users\Cucha\microblog\venv\Lib\site-packages\sqlalchemy\engine\base.py", line 1639, in _execute_clauseelement
    ret = self._execute_context(
          ^^^^^^^^^^^^^^^^^^^^^^
  File "C:\Users\Cucha\microblog\venv\Lib\site-packages\sqlalchemy\engine\base.py", line 1848, in _execute_context
    return self._exec_single_context(
           ^^^^^^^^^^^^^^^^^^^^^^^^^^
  File "C:\Users\Cucha\microblog\venv\Lib\site-packages\sqlalchemy\engine\base.py", line 1988, in _exec_single_context
    self._handle_dbapi_exception(
  File "C:\Users\Cucha\microblog\venv\Lib\site-packages\sqlalchemy\engine\base.py", line 2344, in _handle_dbapi_exception
    raise sqlalchemy_exception.with_traceback(exc_info[2]) from e
  File "C:\Users\Cucha\microblog\venv\Lib\site-packages\sqlalchemy\engine\base.py", line 1969, in _exec_single_context
    self.dialect.do_execute(
  File "C:\Users\Cucha\microblog\venv\Lib\site-packages\sqlalchemy\engine\default.py", line 922, in do_execute
    cursor.execute(statement, parameters)
sqlalchemy.exc.IntegrityError: (sqlite3.IntegrityError) UNIQUE constraint failed: user.username
[SQL: UPDATE user SET username=?, about_me=? WHERE user.id = ?]
[parameters: ('john', "Hi! I'm trying out this new feature I'm developing.", 1)]
(Background on this error at: https://sqlalche.me/e/20/gkpj)
2024-01-12 19:16:01,954 INFO: Microblog startup [in C:\Users\Cucha\microblog\app\__init__.py:47]
2024-01-16 18:26:46,092 INFO: Microblog startup [in C:\Users\Cucha\microblog\app\__init__.py:47]
2024-01-16 18:28:13,692 INFO: Microblog startup [in C:\Users\Cucha\microblog\app\__init__.py:47]
2024-01-16 18:29:21,120 INFO: Microblog startup [in C:\Users\Cucha\microblog\app\__init__.py:47]
2024-01-16 18:30:03,197 INFO: Microblog startup [in C:\Users\Cucha\microblog\app\__init__.py:47]
2024-01-16 18:30:46,503 INFO: Microblog startup [in C:\Users\Cucha\microblog\app\__init__.py:47]
2024-01-17 01:37:48,052 INFO: Microblog startup [in C:\Users\Cucha\microblog\app\__init__.py:49]
2024-01-17 02:43:52,997 INFO: Microblog startup [in C:\Users\Cucha\microblog\app\__init__.py:49]
2024-01-17 02:45:08,799 ERROR: Exception on /reset_password/eyJhbGciOiJIUzI1NiIsInR5cCI6IkpXVCJ9.eyJyZXNldF9wYXNzd29yZCI6NywiZXhwIjoxNzA1NDcwODg2LjU0NDU1OTV9.xZ2CfaWOGwLjclmWvkOX8JHRDQbj-H6n1UzMpIy_0Ys [GET] [in C:\Users\Cucha\microblog\venv\Lib\site-packages\flask\app.py:825]
Traceback (most recent call last):
  File "C:\Users\Cucha\microblog\venv\Lib\site-packages\flask\app.py", line 1455, in wsgi_app
    response = self.full_dispatch_request()
               ^^^^^^^^^^^^^^^^^^^^^^^^^^^^
  File "C:\Users\Cucha\microblog\venv\Lib\site-packages\flask\app.py", line 869, in full_dispatch_request
    rv = self.handle_user_exception(e)
         ^^^^^^^^^^^^^^^^^^^^^^^^^^^^^
  File "C:\Users\Cucha\microblog\venv\Lib\site-packages\flask\app.py", line 867, in full_dispatch_request
    rv = self.dispatch_request()
         ^^^^^^^^^^^^^^^^^^^^^^^
  File "C:\Users\Cucha\microblog\venv\Lib\site-packages\flask\app.py", line 852, in dispatch_request
    return self.ensure_sync(self.view_functions[rule.endpoint])(**view_args)
           ^^^^^^^^^^^^^^^^^^^^^^^^^^^^^^^^^^^^^^^^^^^^^^^^^^^^^^^^^^^^^^^^^
  File "C:\Users\Cucha\microblog\app\routes.py", line 198, in reset_password
    return render_template('reset_password.html', form=form)
          ^^^^^^^^^^^^^^^^^^^^^^^^^^^^^^^^^^^^^^^^^^^^^^^^^
  File "C:\Users\Cucha\microblog\venv\Lib\site-packages\flask\templating.py", line 152, in render_template
    return _render(app, template, context)
           ^^^^^^^^^^^^^^^^^^^^^^^^^^^^^^^
  File "C:\Users\Cucha\microblog\venv\Lib\site-packages\flask\templating.py", line 133, in _render
    rv = template.render(context)
         ^^^^^^^^^^^^^^^^^^^^^^^^
  File "C:\Users\Cucha\microblog\venv\Lib\site-packages\jinja2\environment.py", line 1301, in render
    self.environment.handle_exception()
  File "C:\Users\Cucha\microblog\venv\Lib\site-packages\jinja2\environment.py", line 936, in handle_exception
    raise rewrite_traceback_stack(source=source)
  File "C:\Users\Cucha\microblog\app\templates\reset_password.html", line 1, in top-level template code
    {% extends "base.html" %}
  File "C:\Users\Cucha\microblog\app\templates\base.html", line 32, in top-level template code
    {% block content %}{% endblock %}
    ^^^^^^^^^^^^^^^^^^^^^^^^^
  File "C:\Users\Cucha\microblog\app\templates\reset_password.html", line 21, in block 'content'
    <p>{{ form.submit() }}</p>
    ^^^^^^^^^^^^^^^^^^^^^^^^^
  File "C:\Users\Cucha\microblog\venv\Lib\site-packages\jinja2\utils.py", line 83, in from_obj
    if hasattr(obj, "jinja_pass_arg"):
       ^^^^^^^^^^^^^^^^^^^^^^^^^^^^^^
jinja2.exceptions.UndefinedError: 'app.forms.ResetPasswordForm object' has no attribute 'submit'
2024-01-17 02:51:53,769 INFO: Microblog startup [in C:\Users\Cucha\microblog\app\__init__.py:49]
2024-01-17 02:58:45,861 INFO: Microblog startup [in C:\Users\Cucha\microblog\app\__init__.py:49]
2024-01-17 15:43:35,520 INFO: Microblog startup [in C:\Users\Cucha\microblog\app\__init__.py:49]
2024-01-17 15:48:58,505 INFO: Microblog startup [in C:\Users\Cucha\microblog\app\__init__.py:49]
2024-01-17 15:58:59,631 INFO: Microblog startup [in C:\Users\Cucha\microblog\app\__init__.py:51]
2024-01-17 16:10:34,272 INFO: Microblog startup [in C:\Users\Cucha\microblog\app\__init__.py:51]
2024-01-17 19:04:51,046 INFO: Microblog startup [in C:\Users\Cucha\microblog\app\__init__.py:64]
