2024-01-17 19:04:54,762 ERROR: Exception on / [GET] [in C:\Users\Cucha\microblog\venv\Lib\site-packages\flask\app.py:825]
Traceback (most recent call last):
  File "C:\Users\Cucha\microblog\venv\Lib\site-packages\flask\app.py", line 1455, in wsgi_app
    response = self.full_dispatch_request()
               ^^^^^^^^^^^^^^^^^^^^^^^^^^^^
  File "C:\Users\Cucha\microblog\venv\Lib\site-packages\flask\app.py", line 869, in full_dispatch_request
    rv = self.handle_user_exception(e)
         ^^^^^^^^^^^^^^^^^^^^^^^^^^^^^
  File "C:\Users\Cucha\microblog\venv\Lib\site-packages\flask\app.py", line 867, in full_dispatch_request
    rv = self.dispatch_request()
         ^^^^^^^^^^^^^^^^^^^^^^^
  File "C:\Users\Cucha\microblog\venv\Lib\site-packages\flask\app.py", line 852, in dispatch_request
    return self.ensure_sync(self.view_functions[rule.endpoint])(**view_args)
           ^^^^^^^^^^^^^^^^^^^^^^^^^^^^^^^^^^^^^^^^^^^^^^^^^^^^^^^^^^^^^^^^^
  File "C:\Users\Cucha\microblog\venv\Lib\site-packages\flask_login\utils.py", line 290, in decorated_view
    return current_app.ensure_sync(func)(*args, **kwargs)
           ^^^^^^^^^^^^^^^^^^^^^^^^^^^^^^^^^^^^^^^^^^^^^^
  File "C:\Users\Cucha\microblog\app\routes.py", line 34, in index
    posts = db.paginate(current_user.following_posts(), page=page,
                        ^^^^^^^^^^^^^^^^^^^^^^^^^^^^
AttributeError: 'User' object has no attribute 'following_posts'. Did you mean: 'following_post'?
2024-01-17 19:07:02,193 INFO: Microblog startup [in C:\Users\Cucha\microblog\app\__init__.py:64]
2024-01-17 19:52:39,886 INFO: Microblog startup [in C:\Users\Cucha\microblog\app\__init__.py:64]
2024-01-19 16:09:51,316 INFO: Microblog startup [in C:\Users\Cucha\microblog\app\__init__.py:64]
2024-01-19 16:29:54,721 INFO: Microblog startup [in C:\Users\Cucha\microblog\app\__init__.py:64]
2024-01-19 16:30:14,744 INFO: Microblog startup [in C:\Users\Cucha\microblog\app\__init__.py:64]
2024-01-19 16:47:00,367 INFO: Microblog startup [in C:\Users\Cucha\microblog\app\__init__.py:64]
2024-01-19 16:47:15,171 INFO: Microblog startup [in C:\Users\Cucha\microblog\app\__init__.py:64]
2024-01-19 19:03:39,701 INFO: Microblog startup [in C:\Users\Cucha\microblog\app\__init__.py:64]
2024-01-19 19:05:36,659 INFO: Microblog startup [in C:\Users\Cucha\microblog\app\__init__.py:64]
2024-01-19 19:07:07,141 INFO: Microblog startup [in C:\Users\Cucha\microblog\app\__init__.py:64]
2024-01-19 19:37:12,028 INFO: Microblog startup [in C:\Users\Cucha\microblog\app\__init__.py:64]
2024-01-19 19:39:48,908 INFO: Microblog startup [in C:\Users\Cucha\microblog\app\__init__.py:64]
2024-01-19 19:40:02,018 INFO: Microblog startup [in C:\Users\Cucha\microblog\app\__init__.py:64]
2024-01-19 19:41:32,417 INFO: Microblog startup [in C:\Users\Cucha\microblog\app\__init__.py:64]
2024-01-19 19:46:00,370 INFO: Microblog startup [in C:\Users\Cucha\microblog\app\__init__.py:64]
2024-01-22 16:41:55,134 INFO: Microblog startup [in C:\Users\Cucha\microblog\app\__init__.py:64]
2024-01-22 18:07:37,315 INFO: Microblog startup [in C:\Users\Cucha\microblog\app\__init__.py:83]
2024-01-22 18:07:41,925 ERROR: Exception on /favicon.ico [GET] [in C:\Users\Cucha\microblog\venv\Lib\site-packages\flask\app.py:825]
Traceback (most recent call last):
  File "C:\Users\Cucha\microblog\venv\Lib\site-packages\flask\app.py", line 867, in full_dispatch_request
    rv = self.dispatch_request()
         ^^^^^^^^^^^^^^^^^^^^^^^
  File "C:\Users\Cucha\microblog\venv\Lib\site-packages\flask\app.py", line 841, in dispatch_request
    self.raise_routing_exception(req)
  File "C:\Users\Cucha\microblog\venv\Lib\site-packages\flask\app.py", line 450, in raise_routing_exception
    raise request.routing_exception  # type: ignore
    ^^^^^^^^^^^^^^^^^^^^^^^^^^^^^^^
  File "C:\Users\Cucha\microblog\venv\Lib\site-packages\flask\ctx.py", line 353, in match_request
    result = self.url_adapter.match(return_rule=True)  # type: ignore
             ^^^^^^^^^^^^^^^^^^^^^^^^^^^^^^^^^^^^^^^^
  File "C:\Users\Cucha\microblog\venv\Lib\site-packages\werkzeug\routing\map.py", line 624, in match
    raise NotFound() from None
werkzeug.exceptions.NotFound: 404 Not Found: The requested URL was not found on the server. If you entered the URL manually please check your spelling and try again.

During handling of the above exception, another exception occurred:

Traceback (most recent call last):
  File "C:\Users\Cucha\microblog\venv\Lib\site-packages\flask\app.py", line 1455, in wsgi_app
    response = self.full_dispatch_request()
               ^^^^^^^^^^^^^^^^^^^^^^^^^^^^
  File "C:\Users\Cucha\microblog\venv\Lib\site-packages\flask\app.py", line 869, in full_dispatch_request
    rv = self.handle_user_exception(e)
         ^^^^^^^^^^^^^^^^^^^^^^^^^^^^^
  File "C:\Users\Cucha\microblog\venv\Lib\site-packages\flask\app.py", line 752, in handle_user_exception
    return self.handle_http_exception(e)
           ^^^^^^^^^^^^^^^^^^^^^^^^^^^^^
  File "C:\Users\Cucha\microblog\venv\Lib\site-packages\flask\app.py", line 727, in handle_http_exception
    return self.ensure_sync(handler)(e)
           ^^^^^^^^^^^^^^^^^^^^^^^^^^^^
  File "C:\Users\Cucha\microblog\app\errors\handlers.py", line 7, in not_found_error
    return render_template('404.html'), 404
           ^^^^^^^^^^^^^^^^^^^^^^^^^^^
  File "C:\Users\Cucha\microblog\venv\Lib\site-packages\flask\templating.py", line 151, in render_template
    template = app.jinja_env.get_or_select_template(template_name_or_list)
               ^^^^^^^^^^^^^^^^^^^^^^^^^^^^^^^^^^^^^^^^^^^^^^^^^^^^^^^^^^^
  File "C:\Users\Cucha\microblog\venv\Lib\site-packages\jinja2\environment.py", line 1081, in get_or_select_template
    return self.get_template(template_name_or_list, parent, globals)
           ^^^^^^^^^^^^^^^^^^^^^^^^^^^^^^^^^^^^^^^^^^^^^^^^^^^^^^^^^
  File "C:\Users\Cucha\microblog\venv\Lib\site-packages\jinja2\environment.py", line 1010, in get_template
    return self._load_template(name, globals)
           ^^^^^^^^^^^^^^^^^^^^^^^^^^^^^^^^^^
  File "C:\Users\Cucha\microblog\venv\Lib\site-packages\jinja2\environment.py", line 969, in _load_template
    template = self.loader.load(self, name, self.make_globals(globals))
               ^^^^^^^^^^^^^^^^^^^^^^^^^^^^^^^^^^^^^^^^^^^^^^^^^^^^^^^^
  File "C:\Users\Cucha\microblog\venv\Lib\site-packages\jinja2\loaders.py", line 126, in load
    source, filename, uptodate = self.get_source(environment, name)
                                 ^^^^^^^^^^^^^^^^^^^^^^^^^^^^^^^^^^
  File "C:\Users\Cucha\microblog\venv\Lib\site-packages\flask\templating.py", line 65, in get_source
    return self._get_source_fast(environment, template)
           ^^^^^^^^^^^^^^^^^^^^^^^^^^^^^^^^^^^^^^^^^^^^
  File "C:\Users\Cucha\microblog\venv\Lib\site-packages\flask\templating.py", line 99, in _get_source_fast
    raise TemplateNotFound(template)
jinja2.exceptions.TemplateNotFound: 404.html
2024-01-22 18:08:58,216 ERROR: Exception on /index [POST] [in C:\Users\Cucha\microblog\venv\Lib\site-packages\flask\app.py:825]
Traceback (most recent call last):
  File "C:\Users\Cucha\microblog\venv\Lib\site-packages\flask\app.py", line 1455, in wsgi_app
    response = self.full_dispatch_request()
               ^^^^^^^^^^^^^^^^^^^^^^^^^^^^
  File "C:\Users\Cucha\microblog\venv\Lib\site-packages\flask\app.py", line 869, in full_dispatch_request
    rv = self.handle_user_exception(e)
         ^^^^^^^^^^^^^^^^^^^^^^^^^^^^^
  File "C:\Users\Cucha\microblog\venv\Lib\site-packages\flask\app.py", line 867, in full_dispatch_request
    rv = self.dispatch_request()
         ^^^^^^^^^^^^^^^^^^^^^^^
  File "C:\Users\Cucha\microblog\venv\Lib\site-packages\flask\app.py", line 852, in dispatch_request
    return self.ensure_sync(self.view_functions[rule.endpoint])(**view_args)
           ^^^^^^^^^^^^^^^^^^^^^^^^^^^^^^^^^^^^^^^^^^^^^^^^^^^^^^^^^^^^^^^^^
  File "C:\Users\Cucha\microblog\venv\Lib\site-packages\flask_login\utils.py", line 290, in decorated_view
    return current_app.ensure_sync(func)(*args, **kwargs)
           ^^^^^^^^^^^^^^^^^^^^^^^^^^^^^^^^^^^^^^^^^^^^^^
  File "C:\Users\Cucha\microblog\app\main\routes.py", line 36, in index
    return redirect(url_for('index'))
                    ^^^^^^^^^^^^^^^^
  File "C:\Users\Cucha\microblog\venv\Lib\site-packages\flask\helpers.py", line 222, in url_for
    return current_app.url_for(
           ^^^^^^^^^^^^^^^^^^^^
  File "C:\Users\Cucha\microblog\venv\Lib\site-packages\flask\app.py", line 1071, in url_for
    return self.handle_url_build_error(error, endpoint, values)
           ^^^^^^^^^^^^^^^^^^^^^^^^^^^^^^^^^^^^^^^^^^^^^^^^^^^^
  File "C:\Users\Cucha\microblog\venv\Lib\site-packages\flask\app.py", line 1060, in url_for
    rv = url_adapter.build(  # type: ignore[union-attr]
         ^^^^^^^^^^^^^^^^^^^^^^^^^^^^^^^^^^^^^^^^^^^^^^
  File "C:\Users\Cucha\microblog\venv\Lib\site-packages\werkzeug\routing\map.py", line 919, in build
    raise BuildError(endpoint, values, method, self)
werkzeug.routing.exceptions.BuildError: Could not build url for endpoint 'index'. Did you mean 'main.index' instead?
