2024-02-02 15:30:43,817 INFO: Microblog startup [in /mnt/c/users/cucha/microblog/app/__init__.py:94]
2024-02-02 15:30:51,377 ERROR: Exception on /auth/reset_password_request [POST] [in /home/moi/.local/lib/python3.10/site-packages/flask/app.py:825]
Traceback (most recent call last):
  File "/home/moi/.local/lib/python3.10/site-packages/flask/app.py", line 1455, in wsgi_app
    response = self.full_dispatch_request()
  File "/home/moi/.local/lib/python3.10/site-packages/flask/app.py", line 869, in full_dispatch_request
    rv = self.handle_user_exception(e)
  File "/home/moi/.local/lib/python3.10/site-packages/flask/app.py", line 867, in full_dispatch_request
    rv = self.dispatch_request()
  File "/home/moi/.local/lib/python3.10/site-packages/flask/app.py", line 852, in dispatch_request
    return self.ensure_sync(self.view_functions[rule.endpoint])(**view_args)
  File "/mnt/c/users/cucha/microblog/app/auth/routes.py", line 64, in reset_password_request
    send_password_reset_email(user)
  File "/mnt/c/users/cucha/microblog/app/auth/email.py", line 10, in send_password_reset_email
    text_body=render_template('email/reset_password.txt',
  File "/home/moi/.local/lib/python3.10/site-packages/flask/templating.py", line 152, in render_template
    return _render(app, template, context)
  File "/home/moi/.local/lib/python3.10/site-packages/flask/templating.py", line 133, in _render
    rv = template.render(context)
  File "/home/moi/.local/lib/python3.10/site-packages/jinja2/environment.py", line 1301, in render
    self.environment.handle_exception()
  File "/home/moi/.local/lib/python3.10/site-packages/jinja2/environment.py", line 936, in handle_exception
    raise rewrite_traceback_stack(source=source)
  File "/mnt/c/users/cucha/microblog/app/templates/email/reset_password.txt", line 5, in top-level template code
    {{ url_for('reset_password', token=token, _external=True) }}
  File "/home/moi/.local/lib/python3.10/site-packages/flask/app.py", line 1071, in url_for
    return self.handle_url_build_error(error, endpoint, values)
  File "/home/moi/.local/lib/python3.10/site-packages/flask/app.py", line 1060, in url_for
    rv = url_adapter.build(  # type: ignore[union-attr]
  File "/home/moi/.local/lib/python3.10/site-packages/werkzeug/routing/map.py", line 919, in build
    raise BuildError(endpoint, values, method, self)
werkzeug.routing.exceptions.BuildError: Could not build url for endpoint 'reset_password' with values ['token']. Did you mean 'auth.reset_password' instead?
2024-02-02 15:33:06,303 INFO: Microblog startup [in /mnt/c/users/cucha/microblog/app/__init__.py:94]
2024-02-02 15:49:36,331 INFO: Microblog startup [in /mnt/c/users/cucha/microblog/./app/__init__.py:94]
2024-02-02 15:57:39,103 ERROR: Exception on /api/users [POST] [in /home/moi/.local/lib/python3.10/site-packages/flask/app.py:825]
Traceback (most recent call last):
  File "/home/moi/.local/lib/python3.10/site-packages/flask/app.py", line 1455, in wsgi_app
    response = self.full_dispatch_request()
  File "/home/moi/.local/lib/python3.10/site-packages/flask/app.py", line 870, in full_dispatch_request
    return self.finalize_request(rv)
  File "/home/moi/.local/lib/python3.10/site-packages/flask/app.py", line 889, in finalize_request
    response = self.make_response(rv)
  File "/home/moi/.local/lib/python3.10/site-packages/flask/app.py", line 1161, in make_response
    raise TypeError(
TypeError: The view function for 'api.create_user' did not return a valid response. The function either returned None or ended without a return statement.
2024-02-02 15:59:05,471 ERROR: Exception on /api/users [POST] [in /home/moi/.local/lib/python3.10/site-packages/flask/app.py:825]
Traceback (most recent call last):
  File "/home/moi/.local/lib/python3.10/site-packages/flask/app.py", line 1455, in wsgi_app
    response = self.full_dispatch_request()
  File "/home/moi/.local/lib/python3.10/site-packages/flask/app.py", line 870, in full_dispatch_request
    return self.finalize_request(rv)
  File "/home/moi/.local/lib/python3.10/site-packages/flask/app.py", line 889, in finalize_request
    response = self.make_response(rv)
  File "/home/moi/.local/lib/python3.10/site-packages/flask/app.py", line 1161, in make_response
    raise TypeError(
TypeError: The view function for 'api.create_user' did not return a valid response. The function either returned None or ended without a return statement.
2024-02-02 16:00:36,421 INFO: Microblog startup [in /mnt/c/users/cucha/microblog/app/__init__.py:94]
2024-02-02 16:44:03,155 INFO: Microblog startup [in /mnt/c/users/cucha/microblog/app/__init__.py:94]
2024-02-02 16:44:11,453 INFO: Microblog startup [in /mnt/c/users/cucha/microblog/app/__init__.py:94]
2024-02-02 17:41:22,237 INFO: Microblog startup [in /mnt/c/users/cucha/microblog/app/__init__.py:94]
2024-02-02 17:42:03,522 ERROR: Exception on /api/tokens [POST] [in /home/moi/.local/lib/python3.10/site-packages/flask/app.py:825]
Traceback (most recent call last):
  File "/home/moi/.local/lib/python3.10/site-packages/flask/app.py", line 1455, in wsgi_app
    response = self.full_dispatch_request()
  File "/home/moi/.local/lib/python3.10/site-packages/flask/app.py", line 869, in full_dispatch_request
    rv = self.handle_user_exception(e)
  File "/home/moi/.local/lib/python3.10/site-packages/flask/app.py", line 867, in full_dispatch_request
    rv = self.dispatch_request()
  File "/home/moi/.local/lib/python3.10/site-packages/flask/app.py", line 852, in dispatch_request
    return self.ensure_sync(self.view_functions[rule.endpoint])(**view_args)
  File "/home/moi/.local/lib/python3.10/site-packages/flask_httpauth.py", line 174, in decorated
    return self.ensure_sync(f)(*args, **kwargs)
  File "/mnt/c/users/cucha/microblog/app/api/tokens.py", line 8, in get_token
    token = basic_auth.current_user.get_token()
AttributeError: 'function' object has no attribute 'get_token'
2024-02-02 17:42:37,733 INFO: Microblog startup [in /mnt/c/users/cucha/microblog/app/__init__.py:94]
2024-02-02 17:52:10,265 INFO: Microblog startup [in /mnt/c/users/cucha/microblog/app/__init__.py:94]
2024-02-02 17:59:23,942 INFO: Microblog startup [in /mnt/c/users/cucha/microblog/app/__init__.py:94]
2024-02-09 16:47:07,767 INFO: Microblog startup [in /mnt/c/users/cucha/microblog/app/__init__.py:94]
2024-06-11 08:02:54,698 INFO: Microblog startup [in C:\Users\Cucha\microblog\app\__init__.py:94]
